INFO | 2022-11-29 16:06:30,292 | main | info | log info: /
INFO | 2022-11-29 16:06:33,220 | main | info | log info: /
ERROR | 2022-11-29 16:06:34,391 | app | log_exception | Exception on /home [GET]
Traceback (most recent call last):
  File "D:\Napier\web quiz\venv\lib\site-packages\flask\app.py", line 2525, in wsgi_app
    response = self.full_dispatch_request()
  File "D:\Napier\web quiz\venv\lib\site-packages\flask\app.py", line 1822, in full_dispatch_request
    rv = self.handle_user_exception(e)
  File "D:\Napier\web quiz\venv\lib\site-packages\flask\app.py", line 1820, in full_dispatch_request
    rv = self.dispatch_request()
  File "D:\Napier\web quiz\venv\lib\site-packages\flask\app.py", line 1796, in dispatch_request
    return self.ensure_sync(self.view_functions[rule.endpoint])(**view_args)
  File "D:\Napier\web quiz\main.py", line 129, in home
    data_question, data_options = get_db()
  File "D:\Napier\web quiz\main.py", line 90, in get_db
    cursor.executemany('insert into quiz values (?, ?, ?, ? ,?)', release_list_2)
sqlite3.OperationalError: table quiz has 3 columns but 5 values were supplied
INFO | 2022-11-29 16:08:16,655 | main | info | log info: /
ERROR | 2022-11-29 16:08:18,859 | app | log_exception | Exception on /home [GET]
Traceback (most recent call last):
  File "D:\Napier\web quiz\venv\lib\site-packages\flask\app.py", line 2525, in wsgi_app
    response = self.full_dispatch_request()
  File "D:\Napier\web quiz\venv\lib\site-packages\flask\app.py", line 1822, in full_dispatch_request
    rv = self.handle_user_exception(e)
  File "D:\Napier\web quiz\venv\lib\site-packages\flask\app.py", line 1820, in full_dispatch_request
    rv = self.dispatch_request()
  File "D:\Napier\web quiz\venv\lib\site-packages\flask\app.py", line 1796, in dispatch_request
    return self.ensure_sync(self.view_functions[rule.endpoint])(**view_args)
  File "D:\Napier\web quiz\main.py", line 129, in home
    data_question, data_options = get_db()
  File "D:\Napier\web quiz\main.py", line 90, in get_db
    cursor.executemany('insert into quiz values (?, ?, ?, ? ,?)', release_list_2)
sqlite3.OperationalError: table quiz has 3 columns but 5 values were supplied
INFO | 2022-11-29 16:08:24,384 | main | info | log info: /
INFO | 2022-11-29 16:08:25,217 | main | info | log info: /
INFO | 2022-11-29 16:15:32,398 | main | info | log info: /
INFO | 2022-11-29 16:15:34,819 | main | info | log info: /
ERROR | 2022-11-29 16:15:36,181 | app | log_exception | Exception on /home [GET]
Traceback (most recent call last):
  File "D:\Napier\web quiz\venv\lib\site-packages\flask\app.py", line 2525, in wsgi_app
    response = self.full_dispatch_request()
  File "D:\Napier\web quiz\venv\lib\site-packages\flask\app.py", line 1822, in full_dispatch_request
    rv = self.handle_user_exception(e)
  File "D:\Napier\web quiz\venv\lib\site-packages\flask\app.py", line 1820, in full_dispatch_request
    rv = self.dispatch_request()
  File "D:\Napier\web quiz\venv\lib\site-packages\flask\app.py", line 1796, in dispatch_request
    return self.ensure_sync(self.view_functions[rule.endpoint])(**view_args)
  File "D:\Napier\web quiz\main.py", line 129, in home
    data_question, data_options = get_db()
  File "D:\Napier\web quiz\main.py", line 90, in get_db
    cursor.executemany('insert into quiz values (?, ?, ?, ? ,?)', release_list_2)
sqlite3.OperationalError: table quiz has 3 columns but 5 values were supplied
INFO | 2022-11-29 16:15:38,240 | main | info | log info: /
INFO | 2022-11-29 16:15:40,931 | main | info | log info: /
ERROR | 2022-11-29 16:15:41,005 | app | log_exception | Exception on /home [GET]
Traceback (most recent call last):
  File "D:\Napier\web quiz\venv\lib\site-packages\flask\app.py", line 2525, in wsgi_app
    response = self.full_dispatch_request()
  File "D:\Napier\web quiz\venv\lib\site-packages\flask\app.py", line 1822, in full_dispatch_request
    rv = self.handle_user_exception(e)
  File "D:\Napier\web quiz\venv\lib\site-packages\flask\app.py", line 1820, in full_dispatch_request
    rv = self.dispatch_request()
  File "D:\Napier\web quiz\venv\lib\site-packages\flask\app.py", line 1796, in dispatch_request
    return self.ensure_sync(self.view_functions[rule.endpoint])(**view_args)
  File "D:\Napier\web quiz\main.py", line 129, in home
    data_question, data_options = get_db()
  File "D:\Napier\web quiz\main.py", line 90, in get_db
    cursor.executemany('insert into quiz values (?, ?, ?, ? ,?)', release_list_2)
sqlite3.OperationalError: table quiz has 3 columns but 5 values were supplied
INFO | 2022-11-29 16:15:41,595 | main | info | log info: /
INFO | 2022-12-01 13:15:30,612 | main | info | log info: /
INFO | 2022-12-01 13:15:32,224 | main | info | log info: /
ERROR | 2022-12-01 13:15:33,289 | app | log_exception | Exception on /home [GET]
Traceback (most recent call last):
  File "D:\Napier\web quiz\venv\lib\site-packages\flask\app.py", line 2525, in wsgi_app
    response = self.full_dispatch_request()
  File "D:\Napier\web quiz\venv\lib\site-packages\flask\app.py", line 1822, in full_dispatch_request
    rv = self.handle_user_exception(e)
  File "D:\Napier\web quiz\venv\lib\site-packages\flask\app.py", line 1820, in full_dispatch_request
    rv = self.dispatch_request()
  File "D:\Napier\web quiz\venv\lib\site-packages\flask\app.py", line 1796, in dispatch_request
    return self.ensure_sync(self.view_functions[rule.endpoint])(**view_args)
  File "D:\Napier\web quiz\main.py", line 128, in home
    data_question, data_options = get_db()
  File "D:\Napier\web quiz\main.py", line 89, in get_db
    cursor.executemany('insert into quiz values (?, ?, ?, ? ,?)', release_list_2)
sqlite3.OperationalError: table quiz has 3 columns but 5 values were supplied
INFO | 2022-12-01 13:16:47,015 | main | info | log info: /
INFO | 2022-12-01 13:16:48,128 | main | info | log info: /
ERROR | 2022-12-01 13:16:48,863 | app | log_exception | Exception on /home [GET]
Traceback (most recent call last):
  File "D:\Napier\web quiz\venv\lib\site-packages\flask\app.py", line 2525, in wsgi_app
    response = self.full_dispatch_request()
  File "D:\Napier\web quiz\venv\lib\site-packages\flask\app.py", line 1822, in full_dispatch_request
    rv = self.handle_user_exception(e)
  File "D:\Napier\web quiz\venv\lib\site-packages\flask\app.py", line 1820, in full_dispatch_request
    rv = self.dispatch_request()
  File "D:\Napier\web quiz\venv\lib\site-packages\flask\app.py", line 1796, in dispatch_request
    return self.ensure_sync(self.view_functions[rule.endpoint])(**view_args)
  File "D:\Napier\web quiz\main.py", line 128, in home
    data_question, data_options = get_db()
  File "D:\Napier\web quiz\main.py", line 89, in get_db
    cursor.executemany('insert into quiz values (?, ?, ?)', release_list_2)
sqlite3.ProgrammingError: Incorrect number of bindings supplied. The current statement uses 3, and there are 5 supplied.
INFO | 2022-12-01 13:17:20,653 | main | info | log info: /
ERROR | 2022-12-01 13:17:21,857 | app | log_exception | Exception on /home [GET]
Traceback (most recent call last):
  File "D:\Napier\web quiz\venv\lib\site-packages\flask\app.py", line 2525, in wsgi_app
    response = self.full_dispatch_request()
  File "D:\Napier\web quiz\venv\lib\site-packages\flask\app.py", line 1822, in full_dispatch_request
    rv = self.handle_user_exception(e)
  File "D:\Napier\web quiz\venv\lib\site-packages\flask\app.py", line 1820, in full_dispatch_request
    rv = self.dispatch_request()
  File "D:\Napier\web quiz\venv\lib\site-packages\flask\app.py", line 1796, in dispatch_request
    return self.ensure_sync(self.view_functions[rule.endpoint])(**view_args)
  File "D:\Napier\web quiz\main.py", line 128, in home
    data_question, data_options = get_db()
  File "D:\Napier\web quiz\main.py", line 89, in get_db
    cursor.executemany('insert into quiz values (?, ?, ?, ?, ?)', release_list_2)
sqlite3.OperationalError: table quiz has 3 columns but 5 values were supplied
INFO | 2022-12-01 13:17:45,998 | main | info | log info: /
ERROR | 2022-12-01 13:17:47,667 | app | log_exception | Exception on /home [GET]
Traceback (most recent call last):
  File "D:\Napier\web quiz\venv\lib\site-packages\flask\app.py", line 2525, in wsgi_app
    response = self.full_dispatch_request()
  File "D:\Napier\web quiz\venv\lib\site-packages\flask\app.py", line 1822, in full_dispatch_request
    rv = self.handle_user_exception(e)
  File "D:\Napier\web quiz\venv\lib\site-packages\flask\app.py", line 1820, in full_dispatch_request
    rv = self.dispatch_request()
  File "D:\Napier\web quiz\venv\lib\site-packages\flask\app.py", line 1796, in dispatch_request
    return self.ensure_sync(self.view_functions[rule.endpoint])(**view_args)
  File "D:\Napier\web quiz\main.py", line 128, in home
    data_question, data_options = get_db()
  File "D:\Napier\web quiz\main.py", line 74, in get_db
    cursor.executemany('insert into quiz values (?, ?, ?, ?, ?)', release_list_1)
sqlite3.OperationalError: table quiz has 3 columns but 5 values were supplied
INFO | 2022-12-01 13:27:40,941 | main | info | log info: /
ERROR | 2022-12-01 13:27:42,332 | app | log_exception | Exception on /home [GET]
Traceback (most recent call last):
  File "D:\Napier\web quiz\venv\lib\site-packages\flask\app.py", line 2525, in wsgi_app
    response = self.full_dispatch_request()
  File "D:\Napier\web quiz\venv\lib\site-packages\flask\app.py", line 1822, in full_dispatch_request
    rv = self.handle_user_exception(e)
  File "D:\Napier\web quiz\venv\lib\site-packages\flask\app.py", line 1820, in full_dispatch_request
    rv = self.dispatch_request()
  File "D:\Napier\web quiz\venv\lib\site-packages\flask\app.py", line 1796, in dispatch_request
    return self.ensure_sync(self.view_functions[rule.endpoint])(**view_args)
  File "D:\Napier\web quiz\main.py", line 128, in home
    data_question, data_options = get_db()
  File "D:\Napier\web quiz\main.py", line 89, in get_db
    cursor.executemany('insert into quiz values (?, ?, ?, ?, ?)', release_list_2)
sqlite3.OperationalError: table quiz has 3 columns but 5 values were supplied
INFO | 2022-12-01 13:31:48,579 | main | info | log info: /
ERROR | 2022-12-01 13:31:49,854 | app | log_exception | Exception on /home [GET]
Traceback (most recent call last):
  File "D:\Napier\web quiz\venv\lib\site-packages\flask\app.py", line 2525, in wsgi_app
    response = self.full_dispatch_request()
  File "D:\Napier\web quiz\venv\lib\site-packages\flask\app.py", line 1822, in full_dispatch_request
    rv = self.handle_user_exception(e)
  File "D:\Napier\web quiz\venv\lib\site-packages\flask\app.py", line 1820, in full_dispatch_request
    rv = self.dispatch_request()
  File "D:\Napier\web quiz\venv\lib\site-packages\flask\app.py", line 1796, in dispatch_request
    return self.ensure_sync(self.view_functions[rule.endpoint])(**view_args)
  File "D:\Napier\web quiz\main.py", line 128, in home
    data_question, data_options = get_db()
  File "D:\Napier\web quiz\main.py", line 89, in get_db
    cursor.executemany('insert into quiz values (?, ?, ?)', release_list_2)
sqlite3.ProgrammingError: Incorrect number of bindings supplied. The current statement uses 3, and there are 5 supplied.
INFO | 2022-12-01 13:36:11,029 | main | info | log info: /
ERROR | 2022-12-01 13:36:12,062 | app | log_exception | Exception on /home [GET]
Traceback (most recent call last):
  File "D:\Napier\web quiz\venv\lib\site-packages\flask\app.py", line 2525, in wsgi_app
    response = self.full_dispatch_request()
  File "D:\Napier\web quiz\venv\lib\site-packages\flask\app.py", line 1822, in full_dispatch_request
    rv = self.handle_user_exception(e)
  File "D:\Napier\web quiz\venv\lib\site-packages\flask\app.py", line 1820, in full_dispatch_request
    rv = self.dispatch_request()
  File "D:\Napier\web quiz\venv\lib\site-packages\flask\app.py", line 1796, in dispatch_request
    return self.ensure_sync(self.view_functions[rule.endpoint])(**view_args)
  File "D:\Napier\web quiz\main.py", line 128, in home
    data_question, data_options = get_db()
  File "D:\Napier\web quiz\main.py", line 89, in get_db
    cursor.executemany('insert into option values (?, ?, ?)', release_list_2)
sqlite3.OperationalError: no such table: option
INFO | 2022-12-01 13:36:29,804 | main | info | log info: /
ERROR | 2022-12-01 13:36:31,223 | app | log_exception | Exception on /home [GET]
Traceback (most recent call last):
  File "D:\Napier\web quiz\venv\lib\site-packages\flask\app.py", line 2525, in wsgi_app
    response = self.full_dispatch_request()
  File "D:\Napier\web quiz\venv\lib\site-packages\flask\app.py", line 1822, in full_dispatch_request
    rv = self.handle_user_exception(e)
  File "D:\Napier\web quiz\venv\lib\site-packages\flask\app.py", line 1820, in full_dispatch_request
    rv = self.dispatch_request()
  File "D:\Napier\web quiz\venv\lib\site-packages\flask\app.py", line 1796, in dispatch_request
    return self.ensure_sync(self.view_functions[rule.endpoint])(**view_args)
  File "D:\Napier\web quiz\main.py", line 128, in home
    data_question, data_options = get_db()
  File "D:\Napier\web quiz\main.py", line 89, in get_db
    cursor.executemany('insert into option values (?, ?, ?, ?, ?)', release_list_2)
sqlite3.OperationalError: no such table: option
INFO | 2022-12-01 13:36:49,296 | main | info | log info: /
INFO | 2022-12-01 13:40:07,368 | main | info | log info: /
INFO | 2022-12-01 13:40:09,214 | main | info | log info: /
INFO | 2022-12-01 13:42:15,492 | main | info | log info: /
INFO | 2022-12-01 13:42:17,932 | main | info | log info: /
INFO | 2022-12-01 13:47:45,135 | main | info | log info: /
INFO | 2022-12-01 13:47:46,628 | main | info | log info: /
INFO | 2022-12-01 13:47:53,004 | main | info | log info: /
INFO | 2022-12-01 13:47:53,344 | main | info | log info: /
INFO | 2022-12-01 15:17:13,959 | main | info | log info: /
INFO | 2022-12-01 15:17:16,913 | main | info | log info: /
INFO | 2022-12-01 15:18:23,491 | main | info | log info: /
INFO | 2022-12-01 15:18:23,921 | main | info | log info: /
INFO | 2022-12-01 15:18:57,143 | main | info | log info: /
INFO | 2022-12-01 15:20:15,388 | main | info | log info: /
INFO | 2022-12-01 15:38:57,735 | main | info | log info: /
INFO | 2022-12-01 15:38:58,607 | main | info | log info: /
ERROR | 2022-12-01 16:16:24,610 | app | log_exception | Exception on /leaderboard [GET]
Traceback (most recent call last):
  File "D:\Napier\web quiz\venv\lib\site-packages\flask\app.py", line 2525, in wsgi_app
    response = self.full_dispatch_request()
  File "D:\Napier\web quiz\venv\lib\site-packages\flask\app.py", line 1822, in full_dispatch_request
    rv = self.handle_user_exception(e)
  File "D:\Napier\web quiz\venv\lib\site-packages\flask\app.py", line 1820, in full_dispatch_request
    rv = self.dispatch_request()
  File "D:\Napier\web quiz\venv\lib\site-packages\flask\app.py", line 1796, in dispatch_request
    return self.ensure_sync(self.view_functions[rule.endpoint])(**view_args)
  File "D:\Napier\web quiz\main.py", line 157, in leaderboard
    return render_template('leaderboard.html')
  File "D:\Napier\web quiz\venv\lib\site-packages\flask\templating.py", line 146, in render_template
    template = app.jinja_env.get_or_select_template(template_name_or_list)
  File "D:\Napier\web quiz\venv\lib\site-packages\jinja2\environment.py", line 1081, in get_or_select_template
    return self.get_template(template_name_or_list, parent, globals)
  File "D:\Napier\web quiz\venv\lib\site-packages\jinja2\environment.py", line 1010, in get_template
    return self._load_template(name, globals)
  File "D:\Napier\web quiz\venv\lib\site-packages\jinja2\environment.py", line 969, in _load_template
    template = self.loader.load(self, name, self.make_globals(globals))
  File "D:\Napier\web quiz\venv\lib\site-packages\jinja2\loaders.py", line 126, in load
    source, filename, uptodate = self.get_source(environment, name)
  File "D:\Napier\web quiz\venv\lib\site-packages\flask\templating.py", line 62, in get_source
    return self._get_source_fast(environment, template)
  File "D:\Napier\web quiz\venv\lib\site-packages\flask\templating.py", line 98, in _get_source_fast
    raise TemplateNotFound(template)
jinja2.exceptions.TemplateNotFound: leaderboard.html
INFO | 2022-12-01 16:16:29,696 | main | info | log info: /
INFO | 2022-12-01 16:17:21,791 | main | info | log info: /
INFO | 2022-12-01 16:19:50,324 | main | info | log info: /
INFO | 2022-12-01 16:26:39,035 | main | info | log info: /
INFO | 2022-12-01 16:26:40,082 | main | info | log info: /
INFO | 2022-12-01 16:26:58,947 | main | info | log info: /
INFO | 2022-12-02 12:55:13,200 | main | info | log info: /
INFO | 2022-12-02 12:56:02,915 | main | info | log info: /
INFO | 2022-12-02 12:56:04,580 | main | info | log info: /
INFO | 2022-12-02 12:56:11,417 | main | info | log info: /
INFO | 2022-12-02 12:57:27,733 | main | info | log info: /
INFO | 2022-12-02 12:58:06,007 | main | info | log info: /
INFO | 2022-12-02 12:59:54,093 | main | info | log info: /
INFO | 2022-12-02 12:59:59,711 | main | info | log info: /
INFO | 2022-12-02 13:00:46,168 | main | info | log info: /
INFO | 2022-12-02 13:03:53,255 | main | info | log info: /
INFO | 2022-12-02 13:03:59,873 | main | info | log info: /
INFO | 2022-12-02 13:04:04,944 | main | info | log info: /
INFO | 2022-12-02 13:04:07,519 | main | info | log info: /
INFO | 2022-12-02 13:04:08,567 | main | info | log info: /
INFO | 2022-12-02 13:05:06,971 | main | info | log info: /
INFO | 2022-12-02 13:05:09,168 | main | info | log info: /
INFO | 2022-12-02 13:09:34,823 | main | info | log info: /
INFO | 2022-12-02 13:09:36,517 | main | info | log info: /
INFO | 2022-12-02 13:09:37,337 | main | info | log info: /
INFO | 2022-12-02 13:10:03,244 | main | info | log info: /
INFO | 2022-12-02 13:22:14,772 | main | info | log info: /
INFO | 2022-12-02 13:22:47,028 | main | info | log info: /
INFO | 2022-12-02 13:24:16,928 | main | info | log info: /
INFO | 2022-12-02 13:25:18,136 | main | info | log info: /
INFO | 2022-12-02 13:25:31,928 | main | info | log info: /
INFO | 2022-12-02 13:27:07,554 | main | info | log info: /
INFO | 2022-12-02 13:28:19,307 | main | info | log info: /
INFO | 2022-12-02 13:32:04,521 | main | info | log info: /
INFO | 2022-12-02 13:32:05,554 | main | info | log info: /
INFO | 2022-12-02 13:46:56,905 | main | info | log info: /
INFO | 2022-12-02 14:15:18,386 | main | info | log info: /
INFO | 2022-12-02 16:19:56,206 | main | info | log info: /
INFO | 2022-12-02 16:21:24,203 | main | info | log info: /
INFO | 2022-12-02 16:36:45,224 | main | info | log info: /
INFO | 2022-12-02 19:30:06,309 | main | info | log info: /
INFO | 2022-12-02 19:30:06,862 | main | info | log info: /
INFO | 2022-12-02 19:30:27,711 | main | info | log info: /
INFO | 2022-12-02 19:32:08,890 | main | info | log info: /
INFO | 2022-12-02 19:36:42,105 | main | info | log info: /
INFO | 2022-12-02 19:36:50,495 | main | info | log info: /
INFO | 2022-12-02 19:37:00,390 | main | info | log info: /
INFO | 2022-12-02 22:28:54,780 | main | info | log info: /
INFO | 2022-12-03 11:54:37,481 | main | info | log info: /
INFO | 2022-12-03 14:15:44,393 | main | info | log info: /
INFO | 2022-12-03 14:16:15,938 | main | info | log info: /
INFO | 2022-12-03 15:42:20,556 | main | info | log info: /
INFO | 2022-12-03 16:05:26,634 | main | info | log info: /
INFO | 2022-12-03 16:05:27,527 | main | info | log info: /
INFO | 2022-12-03 16:06:28,862 | main | info | log info: /
ERROR | 2022-12-03 16:17:45,031 | app | log_exception | Exception on /home [GET]
Traceback (most recent call last):
  File "D:\Napier\web quiz\venv\lib\site-packages\flask\app.py", line 2525, in wsgi_app
    response = self.full_dispatch_request()
  File "D:\Napier\web quiz\venv\lib\site-packages\flask\app.py", line 1822, in full_dispatch_request
    rv = self.handle_user_exception(e)
  File "D:\Napier\web quiz\venv\lib\site-packages\flask\app.py", line 1820, in full_dispatch_request
    rv = self.dispatch_request()
  File "D:\Napier\web quiz\venv\lib\site-packages\flask\app.py", line 1796, in dispatch_request
    return self.ensure_sync(self.view_functions[rule.endpoint])(**view_args)
  File "D:\Napier\web quiz\main.py", line 146, in home
    return render_template('home.html', quizs=quizs, options=options)
  File "D:\Napier\web quiz\venv\lib\site-packages\flask\templating.py", line 147, in render_template
    return _render(app, template, context)
  File "D:\Napier\web quiz\venv\lib\site-packages\flask\templating.py", line 130, in _render
    rv = template.render(context)
  File "D:\Napier\web quiz\venv\lib\site-packages\jinja2\environment.py", line 1301, in render
    self.environment.handle_exception()
  File "D:\Napier\web quiz\venv\lib\site-packages\jinja2\environment.py", line 936, in handle_exception
    raise rewrite_traceback_stack(source=source)
  File "D:\Napier\web quiz\templates\home.html", line 1, in top-level template code
    {% extends 'base.html' %}
  File "D:\Napier\web quiz\templates\base.html", line 35, in top-level template code
    {% block content %}
  File "D:\Napier\web quiz\templates\home.html", line 40, in block 'content'
    <button class="w-100 btn btn-lg btn-outline-primary" type="submit" onclick="userchoice({{e[0]}}, '{{x}}' )">
  File "D:\Napier\web quiz\venv\lib\site-packages\jinja2\environment.py", line 466, in getitem
    return obj[argument]
jinja2.exceptions.UndefinedError: 'e' is undefined
ERROR | 2022-12-03 16:17:48,960 | app | log_exception | Exception on /home [GET]
Traceback (most recent call last):
  File "D:\Napier\web quiz\venv\lib\site-packages\flask\app.py", line 2525, in wsgi_app
    response = self.full_dispatch_request()
  File "D:\Napier\web quiz\venv\lib\site-packages\flask\app.py", line 1822, in full_dispatch_request
    rv = self.handle_user_exception(e)
  File "D:\Napier\web quiz\venv\lib\site-packages\flask\app.py", line 1820, in full_dispatch_request
    rv = self.dispatch_request()
  File "D:\Napier\web quiz\venv\lib\site-packages\flask\app.py", line 1796, in dispatch_request
    return self.ensure_sync(self.view_functions[rule.endpoint])(**view_args)
  File "D:\Napier\web quiz\main.py", line 146, in home
    return render_template('home.html', quizs=quizs, options=options)
  File "D:\Napier\web quiz\venv\lib\site-packages\flask\templating.py", line 147, in render_template
    return _render(app, template, context)
  File "D:\Napier\web quiz\venv\lib\site-packages\flask\templating.py", line 130, in _render
    rv = template.render(context)
  File "D:\Napier\web quiz\venv\lib\site-packages\jinja2\environment.py", line 1301, in render
    self.environment.handle_exception()
  File "D:\Napier\web quiz\venv\lib\site-packages\jinja2\environment.py", line 936, in handle_exception
    raise rewrite_traceback_stack(source=source)
  File "D:\Napier\web quiz\templates\home.html", line 1, in top-level template code
    {% extends 'base.html' %}
  File "D:\Napier\web quiz\templates\base.html", line 35, in top-level template code
    {% block content %}
  File "D:\Napier\web quiz\templates\home.html", line 40, in block 'content'
    <button class="w-100 btn btn-lg btn-outline-primary" type="submit" onclick="userchoice({{e[0]}}, '{{x}}' )">
  File "D:\Napier\web quiz\venv\lib\site-packages\jinja2\environment.py", line 466, in getitem
    return obj[argument]
jinja2.exceptions.UndefinedError: 'e' is undefined
ERROR | 2022-12-03 16:17:52,017 | app | log_exception | Exception on /home [GET]
Traceback (most recent call last):
  File "D:\Napier\web quiz\venv\lib\site-packages\flask\app.py", line 2525, in wsgi_app
    response = self.full_dispatch_request()
  File "D:\Napier\web quiz\venv\lib\site-packages\flask\app.py", line 1822, in full_dispatch_request
    rv = self.handle_user_exception(e)
  File "D:\Napier\web quiz\venv\lib\site-packages\flask\app.py", line 1820, in full_dispatch_request
    rv = self.dispatch_request()
  File "D:\Napier\web quiz\venv\lib\site-packages\flask\app.py", line 1796, in dispatch_request
    return self.ensure_sync(self.view_functions[rule.endpoint])(**view_args)
  File "D:\Napier\web quiz\main.py", line 146, in home
    return render_template('home.html', quizs=quizs, options=options)
  File "D:\Napier\web quiz\venv\lib\site-packages\flask\templating.py", line 147, in render_template
    return _render(app, template, context)
  File "D:\Napier\web quiz\venv\lib\site-packages\flask\templating.py", line 130, in _render
    rv = template.render(context)
  File "D:\Napier\web quiz\venv\lib\site-packages\jinja2\environment.py", line 1301, in render
    self.environment.handle_exception()
  File "D:\Napier\web quiz\venv\lib\site-packages\jinja2\environment.py", line 936, in handle_exception
    raise rewrite_traceback_stack(source=source)
  File "D:\Napier\web quiz\templates\home.html", line 1, in top-level template code
    {% extends 'base.html' %}
  File "D:\Napier\web quiz\templates\base.html", line 35, in top-level template code
    {% block content %}
  File "D:\Napier\web quiz\templates\home.html", line 40, in block 'content'
    <button class="w-100 btn btn-lg btn-outline-primary" type="submit" onclick="userchoice({{e[0]}}, '{{x}}' )">
  File "D:\Napier\web quiz\venv\lib\site-packages\jinja2\environment.py", line 466, in getitem
    return obj[argument]
jinja2.exceptions.UndefinedError: 'e' is undefined
